[2024-05-23 09:28:30,438] {taskinstance.py:1179} INFO - Dependencies all met for <TaskInstance: workflow.create_table scheduled__2021-04-17T00:00:00+00:00 [queued]>
[2024-05-23 09:28:30,443] {taskinstance.py:1179} INFO - Dependencies all met for <TaskInstance: workflow.create_table scheduled__2021-04-17T00:00:00+00:00 [queued]>
[2024-05-23 09:28:30,444] {taskinstance.py:1376} INFO - 
--------------------------------------------------------------------------------
[2024-05-23 09:28:30,444] {taskinstance.py:1377} INFO - Starting attempt 1 of 1
[2024-05-23 09:28:30,444] {taskinstance.py:1378} INFO - 
--------------------------------------------------------------------------------
[2024-05-23 09:28:30,452] {taskinstance.py:1397} INFO - Executing <Task(MySqlOperator): create_table> on 2021-04-17 00:00:00+00:00
[2024-05-23 09:28:30,456] {standard_task_runner.py:52} INFO - Started process 409 to run task
[2024-05-23 09:28:30,459] {standard_task_runner.py:79} INFO - Running: ['***', 'tasks', 'run', 'workflow', 'create_table', 'scheduled__2021-04-17T00:00:00+00:00', '--job-id', '44', '--raw', '--subdir', 'DAGS_FOLDER/workflow.py', '--cfg-path', '/tmp/tmphbqrzyjn', '--error-file', '/tmp/tmpd3ofb8ln']
[2024-05-23 09:28:30,459] {standard_task_runner.py:80} INFO - Job 44: Subtask create_table
[2024-05-23 09:28:30,512] {task_command.py:371} INFO - Running <TaskInstance: workflow.create_table scheduled__2021-04-17T00:00:00+00:00 [running]> on host 81e6d48ea239
[2024-05-23 09:28:30,567] {taskinstance.py:1591} INFO - Exporting the following env vars:
AIRFLOW_CTX_DAG_OWNER=***
AIRFLOW_CTX_DAG_ID=workflow
AIRFLOW_CTX_TASK_ID=create_table
AIRFLOW_CTX_EXECUTION_DATE=2021-04-17T00:00:00+00:00
AIRFLOW_CTX_TRY_NUMBER=1
AIRFLOW_CTX_DAG_RUN_ID=scheduled__2021-04-17T00:00:00+00:00
[2024-05-23 09:28:30,567] {mysql.py:82} INFO - Executing: CREATE DATABASE qweql
[2024-05-23 09:28:30,576] {base.py:68} INFO - Using connection ID 'mysql_db' for task execution.
[2024-05-23 09:28:30,578] {dbapi.py:231} INFO - Running statement: CREATE DATABASE qweql, parameters: None
[2024-05-23 09:28:30,580] {taskinstance.py:1909} ERROR - Task failed with exception
Traceback (most recent call last):
  File "/home/airflow/.local/lib/python3.7/site-packages/airflow/providers/mysql/operators/mysql.py", line 84, in execute
    hook.run(self.sql, autocommit=self.autocommit, parameters=self.parameters)
  File "/home/airflow/.local/lib/python3.7/site-packages/airflow/hooks/dbapi.py", line 211, in run
    self._run_command(cur, sql_statement, parameters)
  File "/home/airflow/.local/lib/python3.7/site-packages/airflow/hooks/dbapi.py", line 235, in _run_command
    cur.execute(sql_statement)
  File "/home/airflow/.local/lib/python3.7/site-packages/pymysql/cursors.py", line 148, in execute
    result = self._query(query)
  File "/home/airflow/.local/lib/python3.7/site-packages/pymysql/cursors.py", line 310, in _query
    conn.query(q)
  File "/home/airflow/.local/lib/python3.7/site-packages/pymysql/connections.py", line 548, in query
    self._affected_rows = self._read_query_result(unbuffered=unbuffered)
  File "/home/airflow/.local/lib/python3.7/site-packages/pymysql/connections.py", line 775, in _read_query_result
    result.read()
  File "/home/airflow/.local/lib/python3.7/site-packages/pymysql/connections.py", line 1156, in read
    first_packet = self.connection._read_packet()
  File "/home/airflow/.local/lib/python3.7/site-packages/pymysql/connections.py", line 725, in _read_packet
    packet.raise_for_error()
  File "/home/airflow/.local/lib/python3.7/site-packages/pymysql/protocol.py", line 221, in raise_for_error
    err.raise_mysql_exception(self._data)
  File "/home/airflow/.local/lib/python3.7/site-packages/pymysql/err.py", line 143, in raise_mysql_exception
    raise errorclass(errno, errval)
pymysql.err.ProgrammingError: (1007, "Can't create database 'qweql'; database exists")
[2024-05-23 09:28:30,589] {taskinstance.py:1420} INFO - Marking task as FAILED. dag_id=workflow, task_id=create_table, execution_date=20210417T000000, start_date=20240523T092830, end_date=20240523T092830
[2024-05-23 09:28:30,596] {standard_task_runner.py:97} ERROR - Failed to execute job 44 for task create_table ((1007, "Can't create database 'qweql'; database exists"); 409)
[2024-05-23 09:28:30,632] {local_task_job.py:156} INFO - Task exited with return code 1
[2024-05-23 09:28:30,658] {local_task_job.py:273} INFO - 0 downstream tasks scheduled from follow-on schedule check
